<?xml version="1.0"?>
<robot xmlns:xacro="http://www.ros.org/wiki/xacro" name="swerve">
<xacro:include filename="$(find swerve_description)/urdf/include/velodyne_lidar.xacro"/>
<xacro:include filename="$(find swerve_description)/urdf/include/epson.urdf.xacro"/>

<xacro:property name="brakes_fixed" value="false"/>

<!-- Add joint friction? -->
  <material name="white">
    <color rgba="0.7 0.7 0.7 1"/>
  </material>
  <material name="black">
    <color rgba="0.2 0.2 0.2 1"/>
  </material>

  <link name="base_link">
  </link>

  <xacro:epson name="imu" parent="base_link" update_rate="400" ns="sensors" frame_id="imu_link" topic_name="/sensors/imu">
      <origin xyz="0.24875 0.0 -0.2" rpy="${0/180*pi} ${0/180*pi} ${90/180*pi}"/> <!-- not calibrated properly-->
  </xacro:epson>

  <link name="mabi_attachment">
  </link>
  <joint name="base_link_to_mabi_attachment" type="fixed">
    <parent link="base_link"/>
    <child link="mabi_attachment"/>
    <origin xyz="0 0 -0.0" rpy="0 0 1.570796"/>
  </joint>

  <link name="body">
    <visual>
      <origin rpy="0 0 0" xyz="0 0 0"/>
      <geometry>
        <mesh filename="package://swerve_description/meshes/body.stl" scale="0.001 0.001 0.001"/>
      </geometry>
      <material name="white"/>
    </visual>
    <collision>
      <geometry>
        <box size="0.902 0.800 0.280"/>
      </geometry>
    </collision>
    <inertial>
      <mass value="31.90123643"/>
      <origin xyz="0.000000562323 0 -0.003378692933"/>
      <inertia ixx="3.238567971" ixy="-0.0001169154562" ixz="-0.000000014560378" iyy="3.455603445" iyz="0.0005658238908" izz="6.052079931"/>
    </inertial>
  </link>
  <joint name="base_link_to_body" type="fixed">
    <parent link="base_link"/>
    <child link="body"/>
    <origin xyz="0 0 -0.140"/>
  </joint>

  <link name="arm_rl">
    <visual>
      <origin rpy="${pi} 0 ${3.0*pi/2.0}" xyz="0 0 0"/>
      <geometry>
        <mesh filename="package://swerve_description/meshes/arm_rl.stl" scale="0.001 0.001 0.001"/>
      </geometry>
      <material name="white"/>
    </visual>
    <collision>
      <origin rpy="${pi} 0 ${3.0*pi/2.0}" xyz="0.0 0.232 0.130"/>
      <geometry>
        <box size="0.464 0.090 0.280"/>
      </geometry>
    </collision>
    <inertial>
      <mass value="4.680353119"/>
      <origin xyz="-0.2874248231 -0.000025732551 -0.1327515781"/>
      <inertia ixx="0.03793414031" ixy="0.000004904354526" ixz="-0.003907344591" iyy="0.1401583096" iyz="-0.00001817130601" izz="0.1060310134"/>
    </inertial>
  </link>
  <xacro:if value="${brakes_fixed}">
    <joint name="left_back_brake_joint" type="fixed">
      <parent link="body"/>
      <child link="arm_rl"/>
      <origin rpy="${pi} 0 ${3.0*pi/2.0}" xyz="-0.4031 0.353 0.1295"/>
    </joint>
  </xacro:if>
  <xacro:unless value="${brakes_fixed}">
    <joint name="left_back_brake_joint" type="revolute">
      <parent link="body"/>
      <child link="arm_rl"/>
      <origin rpy="${pi} 0 ${3.0*pi/2.0}" xyz="-0.4031 0.353 0.1295"/>
      <axis xyz="0 0 1"/>
      <limit effort="200.0" lower="-1.571" upper="1.571" velocity="0.5"/>
      <safety_controller k_position="100" k_velocity="100" soft_lower_limit="-1.5" soft_upper_limit="1.5" />
      <joint_properties damping="1.0" friction="0.0"/>

    </joint>
    <transmission name="arm_rl_trans">
    <type>transmission_interface/SimpleTransmission</type>
    <actuator name="$arm_rl_brake">
      <mechanicalReduction>1</mechanicalReduction>
    </actuator>
    <joint name="left_back_brake_joint">
      <hardwareInterface>hardware_interface/VelocityJointInterface</hardwareInterface>
    </joint>
  </transmission>
  </xacro:unless>


  <link name="arm_rr">
    <visual>
      <origin rpy="${pi} 0 ${pi/2.0}" xyz="0 0 0"/>
      <geometry>
        <mesh filename="package://swerve_description/meshes/arm_rr.stl" scale="0.001 0.001 0.001"/>
      </geometry>
      <material name="white"/>
    </visual>
    <collision>
      <origin rpy="${pi} 0 ${pi/2.0}" xyz="0.0 -0.232 0.130"/>
      <geometry>
        <box size="0.464 0.090 0.280"/>
      </geometry>
    </collision>
    <inertial>
      <mass value="4.680353119"/>
      <origin xyz="-0.2874248231 0.000025732551 -0.1327515781"/>
      <inertia ixx="0.03793414031" ixy="-0.000004904354526" ixz="-0.003907344591" iyy="0.1401583096" iyz="-0.00001817130601" izz="0.1060310134"/>
    </inertial>
  </link>
  <xacro:if value="${brakes_fixed}">
    <joint name="right_back_brake_joint" type="fixed">
      <parent link="body"/>
      <child link="arm_rr"/>
      <origin rpy="${pi} 0 ${pi/2.0}" xyz="-0.4031 -0.353 0.1290"/>

    </joint>
  </xacro:if>
  <xacro:unless value="${brakes_fixed}">
    <joint name="right_back_brake_joint" type="revolute">
      <parent link="body"/>
      <child link="arm_rr"/>
      <origin rpy="${pi} 0 ${pi/2.0}" xyz="-0.4031 -0.353 0.1290"/>
      <axis xyz="0 0 1"/>
      <limit effort="200.0" lower="-1.571" upper="1.571" velocity="0.5"/>
      <safety_controller k_position="100" k_velocity="100" soft_lower_limit="-1.5" soft_upper_limit="1.5" />
      <joint_properties damping="1.0" friction="0.0"/>
    </joint>
      <transmission name="arm_rr_trans">
    <type>transmission_interface/SimpleTransmission</type>
    <actuator name="$arm_rr_brake">
      <mechanicalReduction>1</mechanicalReduction>
    </actuator>
    <joint name="right_back_brake_joint">
      <hardwareInterface>hardware_interface/VelocityJointInterface</hardwareInterface>
    </joint>
  </transmission>
  </xacro:unless>


  <link name="arm_fl">
    <visual>
      <origin rpy="${pi} 0 ${3.0*pi/2.0}" xyz="0 0 0"/>
      <geometry>
        <mesh filename="package://swerve_description/meshes/arm_fl.stl" scale="0.001 0.001 0.001"/>
      </geometry>
      <material name="white"/>
    </visual>
    <collision>
      <origin rpy="${pi} 0 ${3.0*pi/2.0}" xyz="0.0 -0.232 0.130"/>
      <geometry>
        <box size="0.464 0.090 0.280"/>
      </geometry>
    </collision>
    <inertial>
      <mass value="4.680353119"/>
      <origin xyz="0.2874248231 -0.000025732551 -0.1327515781"/>
      <inertia ixx="0.03793414031" ixy="0.000004904354526" ixz="0.003907344591" iyy="0.1401583096" iyz="0.00001817130601" izz="0.1060310134"/>
    </inertial>
  </link>
  <xacro:if value="${brakes_fixed}">
    <joint name="left_front_brake_joint" type="fixed">
      <parent link="body"/>
      <child link="arm_fl"/>
      <origin rpy="${pi} 0 ${3.0*pi/2.0}" xyz="0.4031 0.353 0.1295"/>

    </joint>
  </xacro:if>
  <xacro:unless value="${brakes_fixed}">
    <joint name="left_front_brake_joint" type="revolute">
      <parent link="body"/>
      <child link="arm_fl"/>
      <origin rpy="${pi} 0 ${3.0*pi/2.0}" xyz="0.4031 0.353 0.1295"/>
      <axis xyz="0 0 1"/>
      <limit effort="200.0" lower="-1.571" upper="1.571" velocity="0.5"/>
      <safety_controller k_position="100" k_velocity="100" soft_lower_limit="-1.5" soft_upper_limit="1.5" />
      <joint_properties damping="1.0" friction="0.0"/>
    </joint>
      <transmission name="arm_fl_trans">
    <type>transmission_interface/SimpleTransmission</type>
    <actuator name="$arm_fl_brake">
      <mechanicalReduction>1</mechanicalReduction>
    </actuator>
    <joint name="left_front_brake_joint">
      <hardwareInterface>hardware_interface/VelocityJointInterface</hardwareInterface>
    </joint>
  </transmission>
  </xacro:unless>


  <link name="arm_fr">
    <visual>
      <origin rpy="${pi} 0 ${pi/2.0}" xyz="0 0 0"/>
      <geometry>
        <mesh filename="package://swerve_description/meshes/arm_fr.stl" scale="0.001 0.001 0.001"/>
      </geometry>
      <material name="white"/>
    </visual>
    <collision>
      <origin rpy="${pi} 0 ${pi/2.0}" xyz="0.0 0.232 0.130"/>
      <geometry>
        <box size="0.464 0.090 0.280"/>
      </geometry>
    </collision>
    <inertial>
      <mass value="4.680353119"/>
      <origin xyz="0.2874248231 0.000025732551 -0.1327515781"/>
      <inertia ixx="0.03793414031" ixy="-0.000004904354526" ixz="0.003907344591" iyy="0.1401583096" iyz="0.00001817130601" izz="0.1060310134"/>
    </inertial>
  </link>
  <xacro:if value="${brakes_fixed}">
    <joint name="right_front_brake_joint" type="fixed">
      <parent link="body"/>
      <child link="arm_fr"/>
      <origin rpy="${pi} 0 ${pi/2.0}" xyz="0.4031 -0.353 0.1290"/>

    </joint>
  </xacro:if>
  <xacro:unless value="${brakes_fixed}">
    <joint name="right_front_brake_joint" type="revolute">
      <parent link="body"/>
      <child link="arm_fr"/>
      <origin rpy="${pi} 0 ${pi/2.0}" xyz="0.4031 -0.353 0.1290"/>
      <axis xyz="0 0 1"/>
      <limit effort="200.0" lower="-1.571" upper="1.571" velocity="0.5"/>
      <safety_controller k_position="100" k_velocity="100" soft_lower_limit="-1.5" soft_upper_limit="1.5" />
      <joint_properties damping="1.0" friction="0.0"/>
    </joint>
      <transmission name="arm_fr_trans">
    <type>transmission_interface/SimpleTransmission</type>
    <actuator name="$arm_fr_brake">
      <mechanicalReduction>1</mechanicalReduction>
    </actuator>
    <joint name="right_front_brake_joint">
      <hardwareInterface>hardware_interface/VelocityJointInterface</hardwareInterface>
    </joint>
  </transmission>
  </xacro:unless>


  <link name="leg_fl">
    <visual>
      <origin rpy="${pi} 0 ${pi}" xyz="0 0 0"/>
      <geometry>
        <mesh filename="package://swerve_description/meshes/leg_fl.stl" scale="0.001 0.001 0.001"/>
      </geometry>
      <material name="white"/>
    </visual>
    <collision>
      <origin rpy="${pi} 0 0" xyz="0 -0.045 0.166"/>
      <geometry>
        <box size="0.094 0.14 0.322"/>
      </geometry>
    </collision>
    <inertial>
      <mass value="2.953355758"/>
      <origin xyz="0.000025765612 -0.04067071313 -0.2120849525"/>
      <inertia ixx="0.02759751053" ixy="-0.000002760620178" ixz="-0.00000149396864" iyy="0.02582483119" iyz="0.006233490582" izz="0.005391981492"/>
    </inertial>
  </link>
  <joint name="left_front_steer_joint" type="revolute">
    <parent link="arm_fl"/>
    <child link="leg_fl"/>
    <origin rpy="0 0 ${pi/2.0}" xyz="0 -0.4181 0.1244"/>
    <axis xyz="0 0 1"/>
    <limit effort="20.0" lower="-3.341" upper="3.341" velocity="5.76"/>
    <safety_controller k_position="100" k_velocity="100" soft_lower_limit="-3.141" soft_upper_limit="3.141" />
    <joint_properties damping="1.0" friction="5.0"/>
  </joint>
  <transmission name="leg_fl_trans">
    <type>transmission_interface/SimpleTransmission</type>
    <actuator name="$leg_fl_steering">
      <mechanicalReduction>1</mechanicalReduction>
    </actuator>
    <joint name="left_front_steer_joint">
      <hardwareInterface>hardware_interface/VelocityJointInterface</hardwareInterface>
    </joint>
  </transmission>

  <link name="leg_fr">
    <visual>
      <origin rpy="${pi} 0 ${pi}" xyz="0 0 0"/>
      <geometry>
        <mesh filename="package://swerve_description/meshes/leg_fr.stl" scale="0.001 0.001 0.001"/>
      </geometry>
      <material name="white"/>
    </visual>
    <collision>
      <origin rpy="0 0 0" xyz="0 0.045 0.166"/>
      <geometry>
        <box size="0.094 0.14 0.322"/>
      </geometry>
    </collision>
    <inertial>
      <mass value="2.953355758"/>
      <origin xyz="0.000025765612 0.04067071313 -0.2120849525"/>
      <inertia ixx="0.02759751053" ixy="0.000002760620178" ixz="-0.00000149396864" iyy="0.02582483119" iyz="0.006233490582" izz="0.005391981492"/>
    </inertial>
  </link>
  <joint name="right_front_steer_joint" type="revolute">
    <parent link="arm_fr"/>
    <child link="leg_fr"/>
    <origin rpy="0 0 ${3.0*pi/2.0}" xyz="0 0.4181 0.1244"/>
    <axis xyz="0 0 1"/>
    <limit effort="20.0" lower="-3.341" upper="3.341" velocity="5.76"/>
    <safety_controller k_position="100" k_velocity="100" soft_lower_limit="-3.141" soft_upper_limit="3.141" />
    <joint_properties damping="1.0" friction="5.0"/>
  </joint>
  <transmission name="leg_fr_trans">
    <type>transmission_interface/SimpleTransmission</type>
    <actuator name="$leg_fr_steering">
      <mechanicalReduction>1</mechanicalReduction>
    </actuator>
    <joint name="right_front_steer_joint">
      <hardwareInterface>hardware_interface/VelocityJointInterface</hardwareInterface>
    </joint>
  </transmission>

  <link name="leg_rl">
    <visual>
      <origin rpy="${pi} 0 0" xyz="0 0 0"/>
      <geometry>
        <mesh filename="package://swerve_description/meshes/leg_rl.stl" scale="0.001 0.001 0.001"/>
      </geometry>
      <material name="white"/>
    </visual>
    <collision>
      <origin rpy="${pi} 0 0" xyz="0 0.045 0.166"/>
      <geometry>
        <box size="0.094 0.14 0.322"/>
      </geometry>
    </collision>
    <inertial>
      <mass value="2.953355758"/>
      <origin xyz="-0.000025765612 -0.04067071313 -0.2120849525"/>
      <inertia ixx="0.02759751053" ixy="-0.000002760620178" ixz="0.00000149396864" iyy="0.02582483119" iyz="-0.006233490582" izz="0.005391981492"/>
    </inertial>
  </link>
  <joint name="left_back_steer_joint" type="revolute">
    <parent link="arm_rl"/>
    <child link="leg_rl"/>
    <origin rpy="0 0 ${3.0*pi/2.0}" xyz="0 0.4181 0.1244"/>
    <axis xyz="0 0 1"/>
    <limit effort="20.0" lower="-3.341" upper="3.341" velocity="5.76"/>
    <safety_controller k_position="100" k_velocity="100" soft_lower_limit="-3.141" soft_upper_limit="3.141" />
    <joint_properties damping="1.0" friction="5.0"/>
  </joint>
  <transmission name="leg_rl_trans">
    <type>transmission_interface/SimpleTransmission</type>
    <actuator name="$leg_rl_steering">
      <mechanicalReduction>1</mechanicalReduction>
    </actuator>
    <joint name="left_back_steer_joint">
      <hardwareInterface>hardware_interface/VelocityJointInterface</hardwareInterface>
    </joint>
  </transmission>

  <link name="leg_rr">
    <visual>
      <origin rpy="0 ${pi} ${pi}" xyz="0 0 0"/>
      <geometry>
        <mesh filename="package://swerve_description/meshes/leg_rr.stl" scale="0.001 0.001 0.001"/>
      </geometry>
      <material name="white"/>
    </visual>
    <collision>
      <origin rpy="0 ${pi} ${pi}" xyz="0 -0.045 0.166"/>
      <geometry>
        <box size="0.094 0.14 0.322"/>
      </geometry>
    </collision>
    <inertial>
      <mass value="2.953355758"/>
      <origin xyz="-0.000025765612 0.04067071313 -0.2120849525"/>
      <inertia ixx="0.02759751053" ixy="0.000002760620178" ixz="0.00000149396864" iyy="0.02582483119" iyz="-0.006233490582" izz="0.005391981492"/>
    </inertial>
  </link>
  <joint name="right_back_steer_joint" type="revolute">
    <parent link="arm_rr"/>
    <child link="leg_rr"/>
    <origin rpy="0 0 ${pi/2.0}" xyz="0 -0.4181 0.1244"/>
    <axis xyz="0 0 1"/>
    <limit effort="20.0" lower="-3.341" upper="3.341" velocity="5.76"/>
    <safety_controller k_position="100" k_velocity="100" soft_lower_limit="-3.141" soft_upper_limit="3.141" />
    <joint_properties damping="1.0" friction="5.0"/>
  </joint>
  <transmission name="leg_rr_trans">
    <type>transmission_interface/SimpleTransmission</type>
    <actuator name="$leg_rr_steering">
      <mechanicalReduction>1</mechanicalReduction>
    </actuator>
    <joint name="right_back_steer_joint">
      <hardwareInterface>hardware_interface/VelocityJointInterface</hardwareInterface>
    </joint>
  </transmission>

  <link name="wheel_fl">
    <visual>
      <origin rpy="${pi/2.0} 0 0" xyz="0 0 0"/>
      <geometry>
        <mesh filename="package://swerve_description/meshes/wheel_fl.stl" scale="0.001 0.001 0.001"/>
      </geometry>
      <material name="black"/>
    </visual>
    <collision>
      <origin rpy="${pi} 0 0" xyz="0 -0.003 0"/>
      <geometry>
        <cylinder length="0.01" radius = "0.100"/>
      </geometry>
    </collision>
    <inertial>
      <mass value="1.434561237"/>
      <origin xyz="0 -0.003225753823 0"/>
      <inertia ixx="0.003762436739" ixy="0" ixz="0" iyy="0.007084970164" iyz="0" izz="0.003762596989"/>
    </inertial>
  </link>
  <joint name="left_front_wheel_joint" type="continuous">
    <parent link="leg_fl"/>
    <child link="wheel_fl"/>
    <origin rpy="${3.0*pi/2.0} ${pi/2.0} 0" xyz="0 0.0014 0.2746"/>
    <axis xyz="0 0 1"/>
    <limit effort="1000" velocity="11.52"/>
    <safety_controller k_position="100" k_velocity="100"/>
    <joint_properties damping="1.0" friction="5.0"/>
  </joint>
  <transmission name="wheel_fl_trans">
    <type>transmission_interface/SimpleTransmission</type>
    <actuator name="wheel_fl_drive">
      <mechanicalReduction>1</mechanicalReduction>
    </actuator>
    <joint name="left_front_wheel_joint">
      <hardwareInterface>hardware_interface/VelocityJointInterface</hardwareInterface>
    </joint>
  </transmission>
  <gazebo reference="wheel_fl">
    <mu1 value="0.7"/>
    <mu2 value="0.5"/>
    <kp value="300000.0" />
    <kd value="600.0" />
  </gazebo>

  <link name="wheel_fr">
    <visual>
      <origin rpy="${-pi/2.0} 0 0" xyz="0 0 0"/>
      <geometry>
        <mesh filename="package://swerve_description/meshes/wheel_fr.stl" scale="0.001 0.001 0.001"/>
      </geometry>
      <material name="black"/>
    </visual>
    <collision>
      <origin rpy="${pi} 0 0" xyz="0 0.003 0"/>
      <geometry>
        <cylinder length="0.01" radius = "0.100"/>
      </geometry>
    </collision>
    <inertial>
      <mass value="1.434561237"/>
      <origin xyz="0 0.003225753823 0"/>
      <inertia ixx="0.003762436739" ixy="0" ixz="0" iyy="0.007084970164" iyz="0" izz="0.003762596989"/>
    </inertial>
  </link>
  <joint name="right_front_wheel_joint" type="continuous">
    <parent link="leg_fr"/>
    <child link="wheel_fr"/>
    <origin rpy="${pi/2.0} ${pi/2.0} 0" xyz="0 -0.0013 0.2746"/>
    <axis xyz="0 0 1"/>
    <limit effort="1000" velocity="11.52"/>
    <safety_controller k_position="100" k_velocity="100"/>
    <joint_properties damping="1.0" friction="5.0"/>
  </joint>
  <transmission name="wheel_fr_trans">
    <type>transmission_interface/SimpleTransmission</type>
    <actuator name="wheel_fr_drive">
      <mechanicalReduction>1</mechanicalReduction>
    </actuator>
    <joint name="right_front_wheel_joint">
      <hardwareInterface>hardware_interface/VelocityJointInterface</hardwareInterface>
    </joint>
  </transmission>
  <gazebo reference="wheel_fr">
    <mu1 value="0.7"/>
    <mu2 value="0.5"/>
    <kp value="300000.0" />
    <kd value="600.0" />
  </gazebo>

  <link name="wheel_rl">
    <visual>
      <origin rpy="${pi/2.0} 0 0" xyz="0 0 0"/>
      <geometry>
        <mesh filename="package://swerve_description/meshes/wheel_rl.stl" scale="0.001 0.001 0.001"/>
      </geometry>
      <material name="black"/>
    </visual>
    <collision>
      <origin rpy="${pi} 0 0" xyz="0 0.003 0"/>
      <geometry>
        <cylinder length="0.01" radius = "0.100"/>
      </geometry>
    </collision>
    <inertial>
      <mass value="1.434561237"/>
      <origin xyz="0 -0.003225753823 0"/>
      <inertia ixx="0.003762436739" ixy="0" ixz="0" iyy="0.007084970164" iyz="0" izz="0.003762596989"/>
    </inertial>
  </link>
  <joint name="left_back_wheel_joint" type="continuous">
    <parent link="leg_rl"/>
    <child link="wheel_rl"/>
    <origin rpy="${pi/2} ${pi/2} 0" xyz="0 -0.0013 0.2746"/>
    <axis xyz="0 0 1"/>
    <limit effort="1000" velocity="11.52"/>
    <safety_controller k_position="100" k_velocity="100"/>
    <joint_properties damping="1.0" friction="5.0"/>
  </joint>
  <transmission name="wheel_rl_trans">
    <type>transmission_interface/SimpleTransmission</type>
    <actuator name="wheel_rl_drive">
      <mechanicalReduction>1</mechanicalReduction>
    </actuator>
    <joint name="left_back_wheel_joint">
      <hardwareInterface>hardware_interface/VelocityJointInterface</hardwareInterface>
    </joint>
  </transmission>
  <gazebo reference="wheel_rl">
    <mu1 value="0.7"/>
    <mu2 value="0.5"/>
    <kp value="300000.0" />
    <kd value="600.0" />
  </gazebo>

  <link name="wheel_rr">
    <visual>
      <origin rpy="${3.0*pi/2.0} 0 0" xyz="0 0 0"/>
      <geometry>
        <mesh filename="package://swerve_description/meshes/wheel_rr.stl" scale="0.001 0.001 0.001"/>
      </geometry>
      <material name="black"/>
    </visual>
    <collision>
      <origin rpy="${pi} 0 0" xyz="0 0.003 0"/>
      <geometry>
        <cylinder length="0.01" radius = "0.100"/>
      </geometry>
    </collision>
    <inertial>
      <mass value="1.434561237"/>
      <origin xyz="0 0.003225753823 0"/>
      <inertia ixx="0.003762436739" ixy="0" ixz="0" iyy="0.007084970164" iyz="0" izz="0.003762596989"/>
    </inertial>
  </link>
  <joint name="right_back_wheel_joint" type="continuous">
    <parent link="leg_rr"/>
    <child link="wheel_rr"/>
    <origin rpy="${3.0*pi/2.0} ${pi/2.0} 0" xyz="0 -0.0014 0.2746"/>
    <axis xyz="0 0 1"/>
    <limit effort="1000" velocity="11.52"/>
    <safety_controller k_position="100" k_velocity="100"/>
    <joint_properties damping="1.0" friction="5.0"/>
  </joint>
  <transmission name="wheel_rr_trans">
    <type>transmission_interface/SimpleTransmission</type>
    <actuator name="wheel_rr_drive">
      <mechanicalReduction>1</mechanicalReduction>
    </actuator>
    <joint name="right_back_wheel_joint">
      <hardwareInterface>hardware_interface/VelocityJointInterface</hardwareInterface>
    </joint>
  </transmission>
  <gazebo reference="wheel_rr">
    <mu1 value="0.7"/>
    <mu2 value="0.5"/>
    <kp value="300000.0" />
    <kd value="600.0" />
  </gazebo>

  <xacro:velodyne_lidar parent="base_link"/>

  <gazebo>
    <plugin name="gazebo_ros_control" filename="libgazebo_ros_control.so"/>
  </gazebo>

  

</robot>
